Workbook

Sheet Sheet1
A1: Ticker | B1: Date | C1: Open | D1: High | E1: Low | F1: Close | G1: Volume | H1: Daily Return | I1: Cumulative Return Index
A2: AAPL | B2: 45930 | C2: 254.61318 | D2: 255.67215 | E2: 252.86488 | F2: 254.38341 | G2: 37704300 | H2: =IF(A2=A1,(F2-F1)/F1,"") | I2: 1
A3: AAPL | B3: 45931 | C3: 254.793 | D3: 258.53938 | E3: 254.68311 | F3: 255.20261 | G3: 48713900 | H3: =IF(A3=A2,(F3-F2)/F2,"") -> 0.0032203304 | I3: =I2*(1+H3) -> 1.0032203
A4: AAPL | B4: 45932 | C4: 256.3315 | D4: 257.92995 | E4: 253.90386 | F4: 256.88098 | G4: 42630200 | H4: =IF(A4=A3,(F4-F3)/F3,"") -> 0.0065766383 | I4: =I3*(1+H4) -> 1.0098181
A5: AAPL | B5: 45933 | C5: 254.42336 | D5: 258.98893 | E5: 253.70406 | F5: 257.77011 | G5: 49155600 | H5: =IF(A5=A4,(F5-F4)/F4,"") -> 0.0034612513 | I5: =I4*(1+H5) -> 1.0133134
A6: AAPL | B6: 45936 | C6: 257.74014 | D6: 258.81911 | E6: 254.803 | F6: 256.44141 | G6: 44664100 | H6: =IF(A6=A5,(F6-F5)/F5,"") -> -0.0051546117 | I6: =I5*(1+H6) -> 1.0080901
A7: AAPL | B7: 45937 | C7: 256.5613 | D7: 257.15072 | E7: 255.18263 | F7: 256.23163 | G7: 31955800 | H7: =IF(A7=A6,(F7-F6)/F6,"") -> -0.00081803417 | I7: =I6*(1+H7) -> 1.0072655
A8: AAPL | B8: 45938 | C8: 256.27157 | D8: 258.26964 | E8: 255.86197 | F8: 257.81009 | G8: 36496900 | H8: =IF(A8=A7,(F8-F7)/F7,"") -> 0.0061602883 | I8: =I7*(1+H8) -> 1.0134705
A9: AAPL | B9: 45939 | C9: 257.56031 | D9: 257.75013 | E9: 252.89484 | F9: 253.79396 | G9: 38322000 | H9: =IF(A9=A8,(F9-F8)/F8,"") -> -0.015577856 | I9: =I8*(1+H9) -> 0.99768284
A10: AAPL | B10: 45940 | C10: 254.6931 | D10: 256.13171 | E10: 243.7637 | F10: 245.03247 | G10: 61999100 | H10: =IF(A10=A9,(F10-F9)/F9,"") -> -0.034522058 | I10: =I9*(1+H10) -> 0.96324078
A11: AAPL | B11: 45943 | C11: 249.13849 | D11: 249.44818 | E11: 245.32218 | F11: 247.42015 | G11: 38142900 | H11: =IF(A11=A10,(F11-F10)/F10,"") -> 0.0097443414 | I11: =I10*(1+H11) -> 0.97262692
A12: AAPL | B12: 45944 | C12: 246.36118 | D12: 248.609 | E12: 244.46301 | F12: 247.53004 | G12: 35478000 | H12: =IF(A12=A11,(F12-F11)/F11,"") -> 0.00044415864 | I12: =I11*(1+H12) -> 0.97305892
A13: AAPL | B13: 45945 | C13: 249.24839 | D13: 251.57614 | E13: 247.23034 | F13: 249.09853 | G13: 33893600 | H13: =IF(A13=A12,(F13-F12)/F12,"") -> 0.0063365296 | I13: =I12*(1+H13) -> 0.97922474
A14: AAPL | B14: 45946 | C14: 248.00959 | D14: 248.79881 | E14: 244.89261 | F14: 247.21036 | G14: 39777000 | H14: =IF(A14=A13,(F14-F13)/F13,"") -> -0.0075800061 | I14: =I13*(1+H14) -> 0.97180221
... A64: AAPL | B64: 46020 | C64: 272.69 | D64: 274.35999 | E64: 272.35001 | F64: 273.76001 | G64: 23700400 | H64: =IF(A64=A63,(F64-F63)/F63,"") -> 0.0013168101 | I64: =I63*(1+H64) -> 1.0761709
A65: GOOG | B65: 45930 | C65: 242.90152 | D65: 243.51612 | E65: 239.4148 | F65: 243.3912 | G65: 22541200 | H65: =IF(A65=A64,(F65-F64)/F64,"") | I65: 1
A66: GOOG | B66: 45931 | C66: 241.02274 | D66: 246.98885 | E66: 239.04404 | F66: 245.3799 | G66: 23967700 | H66: =IF(A66=A65,(F66-F65)/F65,"") -> 0.0081707687 | I66: =I65*(1+H66) -> 1.0081708
A67: GOOG | B67: 45932 | C67: 245.47984 | D67: 247.47353 | E67: 242.94649 | F67: 246.26932 | G67: 20657500 | H67: =IF(A67=A66,(F67-F66)/F66,"") -> 0.0036246635 | I67: =I66*(1+H67) -> 1.011825
A68: GOOG | B68: 45933 | C68: 245.0701 | D68: 246.95687 | E68: 242.31191 | F68: 246.28931 | G68: 19941400 | H68: =IF(A68=A67,(F68-F67)/F67,"") -> 8.1167292e-05 | I68: =I67*(1+H68) -> 1.0119072
A69: GOOG | B69: 45936 | C69: 245.61975 | D69: 252.03556 | E69: 245.52981 | F69: 251.34601 | G69: 18309000 | H69: =IF(A69=A68,(F69-F68)/F68,"") -> 0.020531552 | I69: =I68*(1+H69) -> 1.0326832
A70: GOOG | B70: 45937 | C70: 248.76769 | D70: 251.38599 | E70: 246.64907 | F70: 246.96887 | G70: 13811200 | H70: =IF(A70=A69,(F70-F69)/F69,"") -> -0.017414783 | I70: =I69*(1+H70) -> 1.0146992
A71: GOOG | B71: 45938 | C71: 246.03947 | D71: 247.09877 | E71: 244.93019 | F71: 245.29996 | G71: 14136500 | H71: =IF(A71=A70,(F71-F70)/F70,"") -> -0.0067575917 | I71: =I70*(1+H71) -> 1.0078423
A72: GOOG | B72: 45939 | C72: 244.90021 | D72: 245.39488 | E72: 239.52371 | F72: 242.05208 | G72: 19375700 | H72: =IF(A72=A71,(F72-F71)/F71,"") -> -0.013240439 | I72: =I71*(1+H72) -> 0.99449805
A73: GOOG | B73: 45940 | C73: 242.00211 | D73: 244.68036 | E73: 236.53068 | F73: 237.33516 | G73: 22449100 | H73: =IF(A73=A72,(F73-F72)/F72,"") -> -0.019487207 | I73: =I72*(1+H73) -> 0.97511806
A74: GOOG | B74: 45943 | C74: 240.87284 | D74: 244.83026 | E74: 240.59302 | F74: 244.48048 | G74: 12465000 | H74: =IF(A74=A73,(F74-F73)/F73,"") -> 0.030106474 | I74: =I73*(1+H74) -> 1.0044754
A75: GOOG | B75: 45944 | C75: 241.59737 | D75: 247.86327 | E75: 241.02074 | F75: 246.02948 | G75: 17705400 | H75: =IF(A75=A74,(F75-F74)/F74,"") -> 0.0063358676 | I75: =I74*(1+H75) -> 1.0108396
A76: GOOG | B76: 45945 | C76: 247.92325 | D76: 252.59519 | E76: 246.62908 | F76: 251.54588 | G76: 16048100 | H76: =IF(A76=A75,(F76-F75)/F75,"") -> 0.022421716 | I76: =I75*(1+H76) -> 1.0335044
A77: GOOG | B77: 45946 | C77: 252.30038 | D77: 257.41204 | E77: 250.50656 | F77: 251.71577 | G77: 18946000 | H77: =IF(A77=A76,(F77-F76)/F76,"") -> 0.00067538914 | I77: =I76*(1+H77) -> 1.0342024
... A127: GOOG | B127: 46020 | C127: 312.82001 | D127: 314.97 | E127: 311.89999 | F127: 314.39001 | G127: 12305800 | H127: =IF(A127=A126,(F127-F126)/F126,"") -> -0.00180968 | I127: =I126*(1+H127) -> 1.2917066
A128: MSFT | B128: 45930 | C128: 512.2812 | D128: 517.19199 | E128: 508.7079 | F128: 516.98242 | G128: 19728200 | H128: =IF(A128=A127,(F128-F127)/F127,"") | I128: 1
A129: MSFT | B129: 45931 | C129: 513.83827 | D129: 519.53763 | E129: 510.7341 | F129: 518.73914 | G129: 22632300 | H129: =IF(A129=A128,(F129-F128)/F128,"") -> 0.0033980147 | I129: =I128*(1+H129) -> 1.003398
A130: MSFT | B130: 45932 | C130: 516.67303 | D130: 520.62559 | E130: 509.72601 | F130: 514.77655 | G130: 21222900 | H130: =IF(A130=A129,(F130-F129)/F129,"") -> -0.0076388789 | I130: =I129*(1+H130) -> 0.99573318
A131: MSFT | B131: 45933 | C131: 516.13395 | D131: 519.51763 | E131: 514.0379 | F131: 516.38348 | G131: 15112300 | H131: =IF(A131=A130,(F131-F130)/F130,"") -> 0.0031216138 | I131: =I130*(1+H131) -> 0.99884147
A132: MSFT | B132: 45936 | C132: 517.64117 | D132: 530.03801 | E132: 517.23196 | F132: 527.58258 | G132: 21388600 | H132: =IF(A132=A131,(F132-F131)/F131,"") -> 0.021687558 | I132: =I131*(1+H132) -> 1.0205039
A133: MSFT | B133: 45937 | C133: 527.30304 | D133: 528.81023 | E133: 520.46587 | F133: 523.0011 | G133: 14615200 | H133: =IF(A133=A132,(F133-F132)/F132,"") -> -0.0086839143 | I133: =I132*(1+H133) -> 1.0116419
A134: MSFT | B134: 45938 | C134: 522.30249 | D134: 525.96562 | E134: 522.11285 | F134: 523.86951 | G134: 13363400 | H134: =IF(A134=A133,(F134-F133)/F133,"") -> 0.0016604328 | I134: =I133*(1+H134) -> 1.0133217
A135: MSFT | B135: 45939 | C135: 521.36425 | D135: 523.35052 | E135: 516.43347 | F135: 521.42413 | G135: 18343600 | H135: =IF(A135=A134,(F135-F134)/F134,"") -> -0.0046679058 | I135: =I134*(1+H135) -> 1.0085916
A136: MSFT | B136: 45940 | C136: 518.66927 | D136: 522.60191 | E136: 508.67796 | F136: 510.00546 | G136: 24133800 | H136: =IF(A136=A135,(F136-F135)/F135,"") -> -0.021899007 | I136: =I135*(1+H136) -> 0.98650446
A137: MSFT | B137: 45943 | C137: 515.44524 | D137: 515.44524 | E137: 510.72409 | F137: 513.08966 | G137: 14284200 | H137: =IF(A137=A136,(F137-F136)/F136,"") -> 0.0060473823 | I137: =I136*(1+H137) -> 0.99247023
A138: MSFT | B138: 45944 | C138: 509.27684 | D138: 514.31742 | E138: 505.05473 | F138: 512.6106 | G138: 14684300 | H138: =IF(A138=A137,(F138-F137)/F137,"") -> -0.0009336866 | I138: =I137*(1+H138) -> 0.99154357
...

Sheet Sheet2
A3: Row Labels | B3: Average of Daily Return | C3: Volatility
A4: AAPL | B4: 0.0012451782 | C4: 0.011100646
A5: GOOG | B5: 0.004305794 | C5: 0.018610071
A6: MSFT | B6: -0.00088873004 | C6: 0.011995893
A7: NFLX | B7: -0.0036424637 | C7: 0.022166247

Sheet Summary
A1: Ticker | B1: Avg Daily Return | C1: Volatility(Daily) | D1: Final Cumulative Index | E1: Annual Volatility
A2: AAPL | B2: =AVERAGEIF(Sheet1!A:A,"AAPL",Sheet1!H:H) -> 0.0012451782 | C2: {=_xlfn.STDEV.S(IF(Sheet1!A:A="AAPL",Sheet1!H:H))} -> 0.011100646 | D2: =LOOKUP(2, 1/(Sheet1!A:A=A2), Sheet1!I:I) -> 1.0761709 | E2: =C2*SQRT(252) -> 0.1762173
A3: GOOG | B3: =AVERAGEIF(Sheet1!A:A,"GOOG",Sheet1!H:H) -> 0.004305794 | C3: {=_xlfn.STDEV.S(IF(Sheet1!A:A="GOOG",Sheet1!H:H))} -> 0.018610071 | D3: =LOOKUP(2, 1/(Sheet1!A:A=A3), Sheet1!I:I) -> 1.2917066 | E3: =C3*SQRT(252) -> 0.29542572
A4: MSFT | B4: =AVERAGEIF(Sheet1!A:A,"MSFT",Sheet1!H:H) -> -0.00088873004 | C4: {=_xlfn.STDEV.S(IF(Sheet1!A:A="MSFT",Sheet1!H:H))} -> 0.011995893 | D4: =LOOKUP(2, 1/(Sheet1!A:A=A4), Sheet1!I:I) -> 0.94219839 | E4: =C4*SQRT(252) -> 0.1904289
A5: NFLX | B5: =AVERAGEIF(Sheet1!A:A,"NFLX",Sheet1!H:H) -> -0.0036424637 | C5: {=_xlfn.STDEV.S(IF(Sheet1!A:A="NFLX",Sheet1!H:H))} -> 0.022166247 | D5: =LOOKUP(2, 1/(Sheet1!A:A=A5), Sheet1!I:I) -> 0.78529012 | E5: =C5*SQRT(252) -> 0.35187826
